A module that was compiled using NumPy 1.x cannot be run in
NumPy 2.2.3 as it may crash. To support both 1.x and 2.x
versions of NumPy, modules must be compiled with NumPy 2.0.
Some module may need to rebuild instead e.g. with 'pybind11>=2.12'.

If you are a user of the module, the easiest solution will be to
downgrade to 'numpy<2' or try to upgrade the affected module.
We expect that some modules will need time to support NumPy 2.

Traceback (most recent call last):  File "/workspace/DreamboothSdTemp/scripts/stable_txt2img.py", line 2, in <module>
    import torch
  File "/usr/local/lib/python3.10/dist-packages/torch/__init__.py", line 1382, in <module>
    from .functional import *  # noqa: F403
  File "/usr/local/lib/python3.10/dist-packages/torch/functional.py", line 7, in <module>
    import torch.nn.functional as F
  File "/usr/local/lib/python3.10/dist-packages/torch/nn/__init__.py", line 1, in <module>
    from .modules import *  # noqa: F403
  File "/usr/local/lib/python3.10/dist-packages/torch/nn/modules/__init__.py", line 35, in <module>
    from .transformer import TransformerEncoder, TransformerDecoder, \
  File "/usr/local/lib/python3.10/dist-packages/torch/nn/modules/transformer.py", line 20, in <module>
    device: torch.device = torch.device(torch._C._get_default_device()),  # torch.device('cpu'),
/usr/local/lib/python3.10/dist-packages/torch/nn/modules/transformer.py:20: UserWarning: Failed to initialize NumPy: _ARRAY_API not found (Triggered internally at ../torch/csrc/utils/tensor_numpy.cpp:84.)
  device: torch.device = torch.device(torch._C._get_default_device()),  # torch.device('cpu'),
Traceback (most recent call last):
  File "/usr/local/lib/python3.10/dist-packages/transformers/utils/import_utils.py", line 1093, in _get_module
    return importlib.import_module("." + module_name, self.__name__)
  File "/usr/lib/python3.10/importlib/__init__.py", line 126, in import_module
    return _bootstrap._gcd_import(name[level:], package, level)
  File "<frozen importlib._bootstrap>", line 1050, in _gcd_import
  File "<frozen importlib._bootstrap>", line 1027, in _find_and_load
  File "<frozen importlib._bootstrap>", line 1006, in _find_and_load_unlocked
  File "<frozen importlib._bootstrap>", line 688, in _load_unlocked
  File "<frozen importlib._bootstrap_external>", line 883, in exec_module
  File "<frozen importlib._bootstrap>", line 241, in _call_with_frames_removed
  File "/usr/local/lib/python3.10/dist-packages/transformers/modeling_utils.py", line 78, in <module>
    from accelerate import __version__ as accelerate_version
  File "/usr/local/lib/python3.10/dist-packages/accelerate/__init__.py", line 16, in <module>
    from .accelerator import Accelerator
  File "/usr/local/lib/python3.10/dist-packages/accelerate/accelerator.py", line 38, in <module>
    from .checkpointing import load_accelerator_state, load_custom_state, save_accelerator_state, save_custom_state
  File "/usr/local/lib/python3.10/dist-packages/accelerate/checkpointing.py", line 21, in <module>
    from safetensors.torch import load_model
ImportError: cannot import name 'load_model' from 'safetensors.torch' (/usr/local/lib/python3.10/dist-packages/safetensors/torch.py)

The above exception was the direct cause of the following exception:

Traceback (most recent call last):
  File "/workspace/DreamboothSdTemp/scripts/stable_txt2img.py", line 11, in <module>
    from pytorch_lightning import seed_everything
  File "/usr/local/lib/python3.10/dist-packages/pytorch_lightning/__init__.py", line 34, in <module>
    from pytorch_lightning.callbacks import Callback  # noqa: E402
  File "/usr/local/lib/python3.10/dist-packages/pytorch_lightning/callbacks/__init__.py", line 14, in <module>
    from pytorch_lightning.callbacks.callback import Callback
  File "/usr/local/lib/python3.10/dist-packages/pytorch_lightning/callbacks/callback.py", line 25, in <module>
    from pytorch_lightning.utilities.types import STEP_OUTPUT
  File "/usr/local/lib/python3.10/dist-packages/pytorch_lightning/utilities/types.py", line 28, in <module>
    from torchmetrics import Metric
  File "/usr/local/lib/python3.10/dist-packages/torchmetrics/__init__.py", line 14, in <module>
    from torchmetrics import functional  # noqa: E402
  File "/usr/local/lib/python3.10/dist-packages/torchmetrics/functional/__init__.py", line 82, in <module>
    from torchmetrics.functional.text.bleu import bleu_score
  File "/usr/local/lib/python3.10/dist-packages/torchmetrics/functional/text/__init__.py", line 30, in <module>
    from torchmetrics.functional.text.bert import bert_score  # noqa: F401
  File "/usr/local/lib/python3.10/dist-packages/torchmetrics/functional/text/bert.py", line 24, in <module>
    from torchmetrics.functional.text.helper_embedding_metric import (
  File "/usr/local/lib/python3.10/dist-packages/torchmetrics/functional/text/helper_embedding_metric.py", line 26, in <module>
    from transformers import AutoModelForMaskedLM, AutoTokenizer, PreTrainedModel, PreTrainedTokenizerBase
  File "<frozen importlib._bootstrap>", line 1075, in _handle_fromlist
  File "/usr/local/lib/python3.10/dist-packages/transformers/utils/import_utils.py", line 1083, in __getattr__
    module = self._get_module(self._class_to_module[name])
  File "/usr/local/lib/python3.10/dist-packages/transformers/utils/import_utils.py", line 1095, in _get_module
    raise RuntimeError(
RuntimeError: Failed to import transformers.modeling_utils because of the following error (look up to see its traceback):
cannot import name 'load_model' from 'safetensors.torch' (/usr/local/lib/python3.10/dist-packages/safetensors/torch.py)
mv: cannot stat 'outputs/txt2img-samples/*.png': No such file or directory
